<?xml version="1.0" encoding="utf-8"?>
<!-- This URDF was automatically created by SolidWorks to URDF Exporter! Originally created by Stephen Brawner (brawner@gmail.com) 
     Commit Version: 1.6.0-4-g7f85cfe  Build Version: 1.6.7995.38578
     For more information, please see http://wiki.ros.org/sw_urdf_exporter -->
<robot
  name="2DOF_Assembly_URDF">

  <link
    name="base_link">
    <inertial>
      <origin
        xyz="9.7691E-05 0.0021368 0.077058"
        rpy="0 0 0" />
      <mass
        value="1.2967" />
      <inertia
        ixx="0.00026781"
        ixy="3.3642E-07"
        ixz="-2.9927E-07"
        iyy="0.00038607"
        iyz="-2.9674E-05"
        izz="0.00030767" />
    </inertial>
    <visual>
      <origin
        xyz="0 0 0"
        rpy="0 0 0" />
      <geometry>
        <mesh
          filename="/home/fan/workspace/IsaacLab/assets/gripper/2DOF_Assembly_URDF/meshes/base_link.obj"/>
      </geometry>
      <material
        name="">
        <color
          rgba="0.29804 0.29804 0.29804 1" />
      </material>
    </visual>
    <collision>
      <origin
        xyz="0 0 0"
        rpy="0 0 0" />
      <geometry>
        <mesh
          filename="/home/fan/workspace/IsaacLab/assets/gripper/2DOF_Assembly_URDF/meshes/base_link.obj"/>
      </geometry>
    </collision>
  </link>
  <link
    name="left_finger">
    <inertial>
      <origin
        xyz="0.036347 -0.0010384 -1.18E-06"
        rpy="0 0 0" />
      <mass
        value="0.1" />
      <inertia
        ixx="0.0001"
        ixy="0"
        ixz="0"
        iyy="0.0001"
        iyz="0"
        izz="0.0001" />
    </inertial>
    <visual>
      <origin
        xyz="0 0 0"
        rpy="0 0 0" />
      <geometry>
        <mesh
          filename="/home/fan/workspace/IsaacLab/assets/gripper/2DOF_Assembly_URDF/meshes/left_finger.obj"/>
      </geometry>
      <material
        name="">
        <color
          rgba="0.29804 0.29804 0.29804 1" />
      </material>
    </visual>
    <collision>
      <origin
        xyz="0 0 0"
        rpy="0 0 0" />
      <geometry>
        <mesh
          filename="/home/fan/workspace/IsaacLab/assets/gripper/2DOF_Assembly_URDF/meshes/left_finger.obj"/>
      </geometry>
    </collision>
  </link>
  <joint
    name="left_joint"
    type="revolute">
    <origin
      xyz="-0.032 0.08 0"
      rpy="3.1416 0 1.5708" />
    <parent
      link="base_link" />
    <child
      link="left_finger" />
    <axis
      xyz="0 0 1" />
    <dynamics damping="0.1" friction="0.1"/>
    <limit
      lower="-0.7"
      upper="0.4"
      effort="10.0"
      velocity="5.0" />
  </joint>
  <link
    name="right_finger">
    <inertial>
      <origin
        xyz="0.036347 -0.0010384 -1.18E-06"
        rpy="0 0 0" />
      <mass
        value="0.1" />
      <inertia
        ixx="0.0001"
        ixy="0"
        ixz="0"
        iyy="0.0001"
        iyz="0"
        izz="0.0001" />
    </inertial>
    <visual>
      <origin
        xyz="0 0 0"
        rpy="0 0 0" />
      <geometry>
        <mesh
          filename="/home/fan/workspace/IsaacLab/assets/gripper/2DOF_Assembly_URDF/meshes/right_finger.obj"/>
      </geometry>
      <material
        name="">
        <color
          rgba="0.29804 0.29804 0.29804 1" />
      </material>
    </visual>
    <collision>
      <origin
        xyz="0 0 0"
        rpy="0 0 0" />
      <geometry>
        <mesh
          filename="/home/fan/workspace/IsaacLab/assets/gripper/2DOF_Assembly_URDF/meshes/right_finger.obj"/>
      </geometry>
    </collision>
  </link>
  <joint
    name="right_joint"
    type="revolute">
    <origin
      xyz="0.032 0.08 0"
      rpy="0 0 1.5708" />
    <parent
      link="base_link" />
    <child
      link="right_finger" />
    <axis
      xyz="0 0 1" />
    <dynamics damping="0.1" friction="0.1"/>
    <limit
      lower="-0.7"
      upper="0.4"
      effort="10.0"
      velocity="5.0" />
  </joint>
</robot>